Workbook
Name _: #REF!
Name _: #REF!
Name _: #REF!
Name _: #REF!
Name _: #REF!
Name _: #REF!
Name __________013: '[1]AN-K'!#REF!
Name __________013: '[1]AN-K'!#REF!
Name __________013: '[1]AN-K'!#REF!
Name __________013: '[1]AN-K'!#REF!
Name __________013: '[1]AN-K'!#REF!
Name __________013: '[1]AN-K'!#REF!
Name __________016: '[1]AN-K'!#REF!
Name __________016: '[1]AN-K'!#REF!
Name __________016: '[1]AN-K'!#REF!
Name __________016: '[1]AN-K'!#REF!
Name __________016: '[1]AN-K'!#REF!
Name __________016: '[1]AN-K'!#REF!
Name __________017: '[1]AN-K'!#REF!
Name __________017: '[1]AN-K'!#REF!
Name __________017: '[1]AN-K'!#REF!
Name __________017: '[1]AN-K'!#REF!
Name __________017: '[1]AN-K'!#REF!
Name __________017: '[1]AN-K'!#REF!
Name __________110: '[1]AN-K'!#REF!
Name __________110: '[1]AN-K'!#REF!
Name __________110: '[1]AN-K'!#REF!
Name __________110: '[1]AN-K'!#REF!
Name __________110: '[1]AN-K'!#REF!
Name __________110: '[1]AN-K'!#REF!
Name __________210: '[1]AN-K'!#REF!
Name __________210: '[1]AN-K'!#REF!
Name __________210: '[1]AN-K'!#REF!
Name __________210: '[1]AN-K'!#REF!
Name __________210: '[1]AN-K'!#REF!
Name __________210: '[1]AN-K'!#REF!
Name __________224: '[1]AN-K'!#REF!
Name __________224: '[1]AN-K'!#REF!
Name __________224: '[1]AN-K'!#REF!
Name __________224: '[1]AN-K'!#REF!
Name __________224: '[1]AN-K'!#REF!
Name __________224: '[1]AN-K'!#REF!
Name __________225: '[1]AN-K'!#REF!
Name __________225: '[1]AN-K'!#REF!
Name __________225: '[1]AN-K'!#REF!
Name __________225: '[1]AN-K'!#REF!
Name __________225: '[1]AN-K'!#REF!
Name __________225: '[1]AN-K'!#REF!
Name __________310: '[1]AN-K'!#REF!
Name __________310: '[1]AN-K'!#REF!
Name __________310: '[1]AN-K'!#REF!
Name __________310: '[1]AN-K'!#REF!
Name __________310: '[1]AN-K'!#REF!
Name __________310: '[1]AN-K'!#REF!
Name __________311: '[1]AN-K'!#REF!
Name __________311: '[1]AN-K'!#REF!
Name __________311: '[1]AN-K'!#REF!
Name __________311: '[1]AN-K'!#REF!
Name __________311: '[1]AN-K'!#REF!
Name __________311: '[1]AN-K'!#REF!

Sheet Sheet1
A1: TEMPLETE INI COCOK UNTUK:
A3: - | B3: MINI MARKET | H3: - | I3: REKANAN PEMERINTAH
A4: - | B4: SWALAYAN | H4: - | I4: USAHA DAGANG LAINNYA
A5: - | B5: TOKO SEMBAKO
A6: - | B6: TOKO BANGUNAN
A7: - | B7: TOKO KELONTONG
A8: - | B8: TOKO ALAT LISTRIK
A9: - | B9: TOKO BUSANA
A10: - | B10: APOTEK
A11: - | B11: JUAL BELI HEWAN TERNAK

Sheet DASHBOARD
A2: 1 | B2: Ringkasan Pendapatan vs Pengeluaran
B3: PENDAPATAN | C3: ='LABA RUGI'!E8+'LABA RUGI'!D31 -> 1.5020892e+08
B4: PENGELUARAN | C4: ='LABA RUGI'!E12+'LABA RUGI'!E27+'LABA RUGI'!D32 -> 13019825
A6: 2 | B6: Ringkasan Pengeluaran Per Kategori
B7: HPP | C7: ='LABA RUGI'!E12 -> 6000000
B8: Biaya Jasa | C8: ='LABA RUGI'!D11 -> 6000000
B9: ='LABA RUGI'!C16 -> Gaji | C9: ='LABA RUGI'!D16 -> 0
B10: ='LABA RUGI'!C17 -> Listrik Internet PDAM | C10: ='LABA RUGI'!D17 -> 1555000
B11: ='LABA RUGI'!C18 -> BPJS | C11: ='LABA RUGI'!D18 -> 5198862
B12: ='LABA RUGI'!C19 -> Operasional | C12: ='LABA RUGI'!D19 -> 0
B13: ='LABA RUGI'!C20 -> Pemasaran | C13: ='LABA RUGI'!D20 -> 0
B14: ='LABA RUGI'!C21 -> Transport | C14: ='LABA RUGI'!D21 -> 0
B15: ='LABA RUGI'!C22 -> Pemeliharaan | C15: ='LABA RUGI'!D22 -> 0
B16: ='LABA RUGI'!C23 -> Sewa | C16: ='LABA RUGI'!D23 -> 0
B17: ='LABA RUGI'!C24 -> Administrasi & Umum | C17: ='LABA RUGI'!D24 -> 32500
B18: Penyusutan Aset | C18: ='LABA RUGI'!D25 -> 0
B19: ='LABA RUGI'!C26 -> Pajak | C19: ='LABA RUGI'!D26 -> 233463.26
B20: Biaya Diluar Usaha | C20: ='LABA RUGI'!D32 -> 0
A21: 3 | B21: Ringkasan Aset Per Kategori
B22: =NERACA!A7 -> Kas dan Bank | C22: =NERACA!B7 -> 60955611
B23: =NERACA!A8 -> Piutang Usaha | C23: =NERACA!B8 -> 0
B24: =NERACA!A9 -> PPh 23 Dibayar Dimuka | C24: =NERACA!B9 -> 0
B25: =NERACA!A10 -> PPh 22 Dibayar Dimuka | C25: =NERACA!B10 -> 0
B26: =NERACA!A11 -> PPh 25 Dibayar Dimuka | C26: =NERACA!B11 -> 0
B27: =NERACA!A12 -> PPN Masukan | C27: =NERACA!B12 -> 0
B28: =NERACA!A13 -> PPN Dibayar Dimuka (Instansi) | C28: =NERACA!B13 -> 0
B29: Aset Tetap | C29: =NERACA!C19 -> 0
A32: 4 | B32: Ringkasan Pasiva Per Kategori
B33: =NERACA!F7 -> Hutang Usaha | C33: =NERACA!G7 -> 0
B34: =NERACA!F8 -> PPN Keluaran | C34: =NERACA!G8 -> 0
B35: =NERACA!F9 -> 0 | C35: =NERACA!G9 -> 0
B36: Ekuitas | C36: =NERACA!H18 -> 1.3718909e+08
A38: 5 | B38: Ringkasan Aset Per Kategori
B39: Tanah dan Bangunan | C39: =ASET!U14 -> 0
B40: Kendaraan | C40: =ASET!U31 -> 0
B41: Furniture | C41: =ASET!U42 -> 0
B42: Peralatan | C42: =ASET!U83 -> 0

Sheet NS
A2: NERACA SALDO
A3: 2026
A5: NO. AKUN | B5: NAMA AKUN | D5: Saldo Normal | E5: POS | F5: NERACA SALDO AWAL | H5: MUTASI | J5: NERACA SALDO AKHIR
F6: DEBET | G6: KREDIT | H6: DEBET | I6: KREDIT | J6: DEBET | K6: KREDIT
A7: 1-111 | B7: Kas | D7: D | E7: NR | H7: =KAS!F1578 -> 0 | I7: =KAS!G1578 -> 0 | J7: =F7+H7-I7 -> 0
A8: 1-112 | B8: BANK MANDIRI - | D8: D | E8: NR | H8: ='BANK 1'!F1437 -> 1.5020892e+08 | I8: ='BANK 1'!G1437 -> 89253305 | J8: =F8+H8-I8 -> 60955611
A9: 1-113 | B9: BANK BJB - | D9: D | E9: NR | H9: ='BANK 2'!F796 -> 0 | I9: ='BANK 2'!G796 -> 0 | J9: =F9+H9-I9 -> 0
A10: 1-114 | B10: BANK BCA - | D10: D | E10: NR | H10: ='BANK 3'!F796 -> 0 | I10: ='BANK 3'!G796 -> 0 | J10: =F10+H10-I10 -> 0
A11: 1-115 | B11: BANK … | D11: D | E11: NR | H11: ='BANK 4'!F2047 -> 0 | I11: ='BANK 4'!G2047 -> 0 | J11: =F11+H11-I11 -> 0
A12: 1-116 | B12: Piutang | D12: D | E12: NR | H12: =(SUMIF(KAS!$C$7:$C$1577,VLOOKUP(NS!B12,$B$7:$B$34,1,FALSE),KAS!$G$7:$G$1577))+(SUMIF('BANK 1'!$C$7:$C$1436,VLOOKUP(NS!B12,$B$7:$B$34,1,FALSE),'BANK 1'!$G$7:$G$1436))+(SUMIF('JURNAL PENYESUAIAN'!$C$7:$C$1434,VLOOKUP(NS!B12,$B$7:$B$34,1,FALSE),'JURNAL PENYESUAIAN'!$G$7:$G$1434))+(SUMIF('BANK 4'!$C$7:$C$2046,VLOOKUP(NS!B12,$B$7:$B$34,1,FALSE),'BANK 4'!$G$7:$G$2046))+(SUMIF('BANK 2'!$C$7:$C$2046,VLOOKUP(NS!B12,$B$7:$B$34,1,FALSE),'BANK 2'!$G$7:$G$2046))+(SUMIF('BANK 3'!$C$7:$C$2046,VLOOKUP(NS!B12,$B$7:$B$34,1,FALSE),'BANK 3'!$G$7:$G$2046)) -> 0 | I12: =(SUMIF(KAS!$C$7:$C$1577,VLOOKUP(NS!B12,$B$7:$B$62,1,FALSE),KAS!$F$7:$F$1577))+(SUMIF('BANK 1'!$C$7:$C$1436,VLOOKUP(NS!B12,$B$7:$B$62,1,FALSE),'BANK 1'!$F$7:$F$1436))+(SUMIF('JURNAL PENYESUAIAN'!$C$7:$C$1434,VLOOKUP(NS!B12,$B$7:$B$62,1,FALSE),'JURNAL PENYESUAIAN'!$F$7:$F$1434))+(SUMIF('BANK 4'!$C$7:$C$2046,VLOOKUP(NS!B12,$B$7:$B$62,1,FALSE),'BANK 4'!$F$7:$F$2046))+(SUMIF('BANK 2'!$C$7:$C$2046,VLOOKUP(NS!B12,$B$7:$B$62,1,FALSE),'BANK 2'!$F$7:$F$2046))+(SUMIF('BANK 3'!$C$7:$C$2046,VLOOKUP(NS!B12,$B$7:$B$62,1,FALSE),'BANK 3'!$F$7:$F$2046)) -> 0 | J12: =F12+H12-I12 -> 0
A13: 1-117 | B13: PPh 23 | D13: D | E13: NR | H13: =(SUMIF(KAS!$C$7:$C$1577,VLOOKUP(NS!B13,$B$7:$B$34,1,FALSE),KAS!$G$7:$G$1577))+(SUMIF('BANK 1'!$C$7:$C$1436,VLOOKUP(NS!B13,$B$7:$B$34,1,FALSE),'BANK 1'!$G$7:$G$1436))+(SUMIF('JURNAL PENYESUAIAN'!$C$7:$C$1434,VLOOKUP(NS!B13,$B$7:$B$34,1,FALSE),'JURNAL PENYESUAIAN'!$G$7:$G$1434))+(SUMIF('BANK 4'!$C$7:$C$2046,VLOOKUP(NS!B13,$B$7:$B$34,1,FALSE),'BANK 4'!$G$7:$G$2046))+(SUMIF('BANK 2'!$C$7:$C$2046,VLOOKUP(NS!B13,$B$7:$B$34,1,FALSE),'BANK 2'!$G$7:$G$2046))+(SUMIF('BANK 3'!$C$7:$C$2046,VLOOKUP(NS!B13,$B$7:$B$34,1,FALSE),'BANK 3'!$G$7:$G$2046)) -> 0 | I13: =(SUMIF(KAS!$C$7:$C$1577,VLOOKUP(NS!B13,$B$7:$B$62,1,FALSE),KAS!$F$7:$F$1577))+(SUMIF('BANK 1'!$C$7:$C$1436,VLOOKUP(NS!B13,$B$7:$B$62,1,FALSE),'BANK 1'!$F$7:$F$1436))+(SUMIF('JURNAL PENYESUAIAN'!$C$7:$C$1434,VLOOKUP(NS!B13,$B$7:$B$62,1,FALSE),'JURNAL PENYESUAIAN'!$F$7:$F$1434))+(SUMIF('BANK 4'!$C$7:$C$2046,VLOOKUP(NS!B13,$B$7:$B$62,1,FALSE),'BANK 4'!$F$7:$F$2046))+(SUMIF('BANK 2'!$C$7:$C$2046,VLOOKUP(NS!B13,$B$7:$B$62,1,FALSE),'BANK 2'!$F$7:$F$2046))+(SUMIF('BANK 3'!$C$7:$C$2046,VLOOKUP(NS!B13,$B$7:$B$62,1,FALSE),'BANK 3'!$F$7:$F$2046)) -> 0 | J13: =F13+H13-I13 -> 0
A14: 1-118 | B14: PPh 22 | D14: D | E14: NR | H14: =(SUMIF(KAS!$C$7:$C$1577,VLOOKUP(NS!B14,$B$7:$B$34,1,FALSE),KAS!$G$7:$G$1577))+(SUMIF('BANK 1'!$C$7:$C$1436,VLOOKUP(NS!B14,$B$7:$B$34,1,FALSE),'BANK 1'!$G$7:$G$1436))+(SUMIF('JURNAL PENYESUAIAN'!$C$7:$C$1434,VLOOKUP(NS!B14,$B$7:$B$34,1,FALSE),'JURNAL PENYESUAIAN'!$G$7:$G$1434))+(SUMIF('BANK 4'!$C$7:$C$2046,VLOOKUP(NS!B14,$B$7:$B$34,1,FALSE),'BANK 4'!$G$7:$G$2046))+(SUMIF('BANK 2'!$C$7:$C$2046,VLOOKUP(NS!B14,$B$7:$B$34,1,FALSE),'BANK 2'!$G$7:$G$2046))+(SUMIF('BANK 3'!$C$7:$C$2046,VLOOKUP(NS!B14,$B$7:$B$34,1,FALSE),'BANK 3'!$G$7:$G$2046)) -> 0 | I14: =(SUMIF(KAS!$C$7:$C$1577,VLOOKUP(NS!B14,$B$7:$B$62,1,FALSE),KAS!$F$7:$F$1577))+(SUMIF('BANK 1'!$C$7:$C$1436,VLOOKUP(NS!B14,$B$7:$B$62,1,FALSE),'BANK 1'!$F$7:$F$1436))+(SUMIF('JURNAL PENYESUAIAN'!$C$7:$C$1434,VLOOKUP(NS!B14,$B$7:$B$62,1,FALSE),'JURNAL PENYESUAIAN'!$F$7:$F$1434))+(SUMIF('BANK 4'!$C$7:$C$2046,VLOOKUP(NS!B14,$B$7:$B$62,1,FALSE),'BANK 4'!$F$7:$F$2046))+(SUMIF('BANK 2'!$C$7:$C$2046,VLOOKUP(NS!B14,$B$7:$B$62,1,FALSE),'BANK 2'!$F$7:$F$2046))+(SUMIF('BANK 3'!$C$7:$C$2046,VLOOKUP(NS!B14,$B$7:$B$62,1,FALSE),'BANK 3'!$F$7:$F$2046)) -> 0 | J14: =F14+H14-I14 -> 0
A15: 1-119 | B15: PPh 25 | D15: D | E15: NR | H15: =(SUMIF(KAS!$C$7:$C$1577,VLOOKUP(NS!B15,$B$7:$B$34,1,FALSE),KAS!$G$7:$G$1577))+(SUMIF('BANK 1'!$C$7:$C$1436,VLOOKUP(NS!B15,$B$7:$B$34,1,FALSE),'BANK 1'!$G$7:$G$1436))+(SUMIF('JURNAL PENYESUAIAN'!$C$7:$C$1434,VLOOKUP(NS!B15,$B$7:$B$34,1,FALSE),'JURNAL PENYESUAIAN'!$G$7:$G$1434))+(SUMIF('BANK 4'!$C$7:$C$2046,VLOOKUP(NS!B15,$B$7:$B$34,1,FALSE),'BANK 4'!$G$7:$G$2046))+(SUMIF('BANK 2'!$C$7:$C$2046,VLOOKUP(NS!B15,$B$7:$B$34,1,FALSE),'BANK 2'!$G$7:$G$2046))+(SUMIF('BANK 3'!$C$7:$C$2046,VLOOKUP(NS!B15,$B$7:$B$34,1,FALSE),'BANK 3'!$G$7:$G$2046)) -> 0 | I15: =(SUMIF(KAS!$C$7:$C$1577,VLOOKUP(NS!B15,$B$7:$B$62,1,FALSE),KAS!$F$7:$F$1577))+(SUMIF('BANK 1'!$C$7:$C$1436,VLOOKUP(NS!B15,$B$7:$B$62,1,FALSE),'BANK 1'!$F$7:$F$1436))+(SUMIF('JURNAL PENYESUAIAN'!$C$7:$C$1434,VLOOKUP(NS!B15,$B$7:$B$62,1,FALSE),'JURNAL PENYESUAIAN'!$F$7:$F$1434))+(SUMIF('BANK 4'!$C$7:$C$2046,VLOOKUP(NS!B15,$B$7:$B$62,1,FALSE),'BANK 4'!$F$7:$F$2046))+(SUMIF('BANK 2'!$C$7:$C$2046,VLOOKUP(NS!B15,$B$7:$B$62,1,FALSE),'BANK 2'!$F$7:$F$2046))+(SUMIF('BANK 3'!$C$7:$C$2046,VLOOKUP(NS!B15,$B$7:$B$62,1,FALSE),'BANK 3'!$F$7:$F$2046)) -> 0 | J15: =F15+H15-I15 -> 0
A16: 1-120 | B16: PPN Masukan | D16: D | E16: NR | H16: =(SUMIF(KAS!$C$7:$C$1577,VLOOKUP(NS!B16,$B$7:$B$34,1,FALSE),KAS!$G$7:$G$1577))+(SUMIF('BANK 1'!$C$7:$C$1436,VLOOKUP(NS!B16,$B$7:$B$34,1,FALSE),'BANK 1'!$G$7:$G$1436))+(SUMIF('JURNAL PENYESUAIAN'!$C$7:$C$1434,VLOOKUP(NS!B16,$B$7:$B$34,1,FALSE),'JURNAL PENYESUAIAN'!$G$7:$G$1434))+(SUMIF('BANK 4'!$C$7:$C$2046,VLOOKUP(NS!B16,$B$7:$B$34,1,FALSE),'BANK 4'!$G$7:$G$2046))+(SUMIF('BANK 2'!$C$7:$C$2046,VLOOKUP(NS!B16,$B$7:$B$34,1,FALSE),'BANK 2'!$G$7:$G$2046))+(SUMIF('BANK 3'!$C$7:$C$2046,VLOOKUP(NS!B16,$B$7:$B$34,1,FALSE),'BANK 3'!$G$7:$G$2046)) -> 0 | I16: =(SUMIF(KAS!$C$7:$C$1577,VLOOKUP(NS!B16,$B$7:$B$62,1,FALSE),KAS!$F$7:$F$1577))+(SUMIF('BANK 1'!$C$7:$C$1436,VLOOKUP(NS!B16,$B$7:$B$62,1,FALSE),'BANK 1'!$F$7:$F$1436))+(SUMIF('JURNAL PENYESUAIAN'!$C$7:$C$1434,VLOOKUP(NS!B16,$B$7:$B$62,1,FALSE),'JURNAL PENYESUAIAN'!$F$7:$F$1434))+(SUMIF('BANK 4'!$C$7:$C$2046,VLOOKUP(NS!B16,$B$7:$B$62,1,FALSE),'BANK 4'!$F$7:$F$2046))+(SUMIF('BANK 2'!$C$7:$C$2046,VLOOKUP(NS!B16,$B$7:$B$62,1,FALSE),'BANK 2'!$F$7:$F$2046))+(SUMIF('BANK 3'!$C$7:$C$2046,VLOOKUP(NS!B16,$B$7:$B$62,1,FALSE),'BANK 3'!$F$7:$F$2046)) -> 0 | J16: =F16+H16-I16 -> 0
A17: 1-121 | B17: PPN Instansi | D17: D | E17: NR | H17: =(SUMIF(KAS!$C$7:$C$1577,VLOOKUP(NS!B17,$B$7:$B$34,1,FALSE),KAS!$G$7:$G$1577))+(SUMIF('BANK 1'!$C$7:$C$1436,VLOOKUP(NS!B17,$B$7:$B$34,1,FALSE),'BANK 1'!$G$7:$G$1436))+(SUMIF('JURNAL PENYESUAIAN'!$C$7:$C$1434,VLOOKUP(NS!B17,$B$7:$B$34,1,FALSE),'JURNAL PENYESUAIAN'!$G$7:$G$1434))+(SUMIF('BANK 4'!$C$7:$C$2046,VLOOKUP(NS!B17,$B$7:$B$34,1,FALSE),'BANK 4'!$G$7:$G$2046))+(SUMIF('BANK 2'!$C$7:$C$2046,VLOOKUP(NS!B17,$B$7:$B$34,1,FALSE),'BANK 2'!$G$7:$G$2046))+(SUMIF('BANK 3'!$C$7:$C$2046,VLOOKUP(NS!B17,$B$7:$B$34,1,FALSE),'BANK 3'!$G$7:$G$2046)) -> 0 | I17: =(SUMIF(KAS!$C$7:$C$1577,VLOOKUP(NS!B17,$B$7:$B$62,1,FALSE),KAS!$F$7:$F$1577))+(SUMIF('BANK 1'!$C$7:$C$1436,VLOOKUP(NS!B17,$B$7:$B$62,1,FALSE),'BANK 1'!$F$7:$F$1436))+(SUMIF('JURNAL PENYESUAIAN'!$C$7:$C$1434,VLOOKUP(NS!B17,$B$7:$B$62,1,FALSE),'JURNAL PENYESUAIAN'!$F$7:$F$1434))+(SUMIF('BANK 4'!$C$7:$C$2046,VLOOKUP(NS!B17,$B$7:$B$62,1,FALSE),'BANK 4'!$F$7:$F$2046))+(SUMIF('BANK 2'!$C$7:$C$2046,VLOOKUP(NS!B17,$B$7:$B$62,1,FALSE),'BANK 2'!$F$7:$F$2046))+(SUMIF('BANK 3'!$C$7:$C$2046,VLOOKUP(NS!B17,$B$7:$B$62,1,FALSE),'BANK 3'!$F$7:$F$2046)) -> 0 | J17: =F17+H17-I17 -> 0
A18: 1-122 | B18: PPN Keluaran | D18: K | E18: NR | H18: =(SUMIF(KAS!$C$7:$C$1577,VLOOKUP(NS!B18,$B$7:$B$34,1,FALSE),KAS!$G$7:$G$1577))+(SUMIF('BANK 1'!$C$7:$C$1436,VLOOKUP(NS!B18,$B$7:$B$34,1,FALSE),'BANK 1'!$G$7:$G$1436))+(SUMIF('JURNAL PENYESUAIAN'!$C$7:$C$1434,VLOOKUP(NS!B18,$B$7:$B$34,1,FALSE),'JURNAL PENYESUAIAN'!$G$7:$G$1434))+(SUMIF('BANK 4'!$C$7:$C$2046,VLOOKUP(NS!B18,$B$7:$B$34,1,FALSE),'BANK 4'!$G$7:$G$2046))+(SUMIF('BANK 2'!$C$7:$C$2046,VLOOKUP(NS!B18,$B$7:$B$34,1,FALSE),'BANK 2'!$G$7:$G$2046))+(SUMIF('BANK 3'!$C$7:$C$2046,VLOOKUP(NS!B18,$B$7:$B$34,1,FALSE),'BANK 3'!$G$7:$G$2046)) -> 0 | I18: =(SUMIF(KAS!$C$7:$C$1577,VLOOKUP(NS!B18,$B$7:$B$62,1,FALSE),KAS!$F$7:$F$1577))+(SUMIF('BANK 1'!$C$7:$C$1436,VLOOKUP(NS!B18,$B$7:$B$62,1,FALSE),'BANK 1'!$F$7:$F$1436))+(SUMIF('JURNAL PENYESUAIAN'!$C$7:$C$1434,VLOOKUP(NS!B18,$B$7:$B$62,1,FALSE),'JURNAL PENYESUAIAN'!$F$7:$F$1434))+(SUMIF('BANK 4'!$C$7:$C$2046,VLOOKUP(NS!B18,$B$7:$B$62,1,FALSE),'BANK 4'!$F$7:$F$2046))+(SUMIF('BANK 2'!$C$7:$C$2046,VLOOKUP(NS!B18,$B$7:$B$62,1,FALSE),'BANK 2'!$F$7:$F$2046))+(SUMIF('BANK 3'!$C$7:$C$2046,VLOOKUP(NS!B18,$B$7:$B$62,1,FALSE),'BANK 3'!$F$7:$F$2046)) -> 0 | K18: =G18+I18-H18 -> 0
A19: 1-211 | B19: Aset Tetap | D19: D | E19: NR | H19: =(SUMIF(KAS!$C$7:$C$1577,VLOOKUP(NS!B19,$B$7:$B$34,1,FALSE),KAS!$G$7:$G$1577))+(SUMIF('BANK 1'!$C$7:$C$1436,VLOOKUP(NS!B19,$B$7:$B$34,1,FALSE),'BANK 1'!$G$7:$G$1436))+(SUMIF('JURNAL PENYESUAIAN'!$C$7:$C$1434,VLOOKUP(NS!B19,$B$7:$B$34,1,FALSE),'JURNAL PENYESUAIAN'!$G$7:$G$1434))+(SUMIF('BANK 4'!$C$7:$C$2046,VLOOKUP(NS!B19,$B$7:$B$34,1,FALSE),'BANK 4'!$G$7:$G$2046))+(SUMIF('BANK 2'!$C$7:$C$2046,VLOOKUP(NS!B19,$B$7:$B$34,1,FALSE),'BANK 2'!$G$7:$G$2046))+(SUMIF('BANK 3'!$C$7:$C$2046,VLOOKUP(NS!B19,$B$7:$B$34,1,FALSE),'BANK 3'!$G$7:$G$2046)) -> 0 | J19: =F19+H19 -> 0
A20: 1-212 | B20: Akm. Penyusutan Aset Tetap | D20: K | E20: NR | K20: =ASET!T86 -> 0
A21: 2-111 | B21: Hutang | D21: K | E21: NR | H21: =(SUMIF(KAS!$C$7:$C$1577,VLOOKUP(NS!B21,$B$7:$B$34,1,FALSE),KAS!$G$7:$G$1577))+(SUMIF('BANK 1'!$C$7:$C$1436,VLOOKUP(NS!B21,$B$7:$B$34,1,FALSE),'BANK 1'!$G$7:$G$1436))+(SUMIF('JURNAL PENYESUAIAN'!$C$7:$C$1434,VLOOKUP(NS!B21,$B$7:$B$34,1,FALSE),'JURNAL PENYESUAIAN'!$G$7:$G$1434))+(SUMIF('BANK 4'!$C$7:$C$2046,VLOOKUP(NS!B21,$B$7:$B$34,1,FALSE),'BANK 4'!$G$7:$G$2046))+(SUMIF('BANK 2'!$C$7:$C$2046,VLOOKUP(NS!B21,$B$7:$B$34,1,FALSE),'BANK 2'!$G$7:$G$2046))+(SUMIF('BANK 3'!$C$7:$C$2046,VLOOKUP(NS!B21,$B$7:$B$34,1,FALSE),'BANK 3'!$G$7:$G$2046)) -> 0 | I21: =(SUMIF(KAS!$C$7:$C$1577,VLOOKUP(NS!B21,$B$7:$B$62,1,FALSE),KAS!$F$7:$F$1577))+(SUMIF('BANK 1'!$C$7:$C$1436,VLOOKUP(NS!B21,$B$7:$B$62,1,FALSE),'BANK 1'!$F$7:$F$1436))+(SUMIF('JURNAL PENYESUAIAN'!$C$7:$C$1434,VLOOKUP(NS!B21,$B$7:$B$62,1,FALSE),'JURNAL PENYESUAIAN'!$F$7:$F$1434))+(SUMIF('BANK 4'!$C$7:$C$2046,VLOOKUP(NS!B21,$B$7:$B$62,1,FALSE),'BANK 4'!$F$7:$F$2046))+(SUMIF('BANK 2'!$C$7:$C$2046,VLOOKUP(NS!B21,$B$7:$B$62,1,FALSE),'BANK 2'!$F$7:$F$2046))+(SUMIF('BANK 3'!$C$7:$C$2046,VLOOKUP(NS!B21,$B$7:$B$62,1,FALSE),'BANK 3'!$F$7:$F$2046)) -> 0 | K21: =G21+I21-H21 -> 0
A22: 3-111 | B22: Modal | D22: K | E22: NR | I22: =(SUMIF(KAS!$C$7:$C$1577,VLOOKUP(NS!B22,$B$7:$B$62,1,FALSE),KAS!$F$7:$F$1577))+(SUMIF('BANK 1'!$C$7:$C$1436,VLOOKUP(NS!B22,$B$7:$B$62,1,FALSE),'BANK 1'!$F$7:$F$1436))+(SUMIF('JURNAL PENYESUAIAN'!$C$7:$C$1434,VLOOKUP(NS!B22,$B$7:$B$62,1,FALSE),'JURNAL PENYESUAIAN'!$F$7:$F$1434))+(SUMIF('BANK 4'!$C$7:$C$2046,VLOOKUP(NS!B22,$B$7:$B$62,1,FALSE),'BANK 4'!$F$7:$F$2046))+(SUMIF('BANK 2'!$C$7:$C$2046,VLOOKUP(NS!B22,$B$7:$B$62,1,FALSE),'BANK 2'!$F$7:$F$2046))+(SUMIF('BANK 3'!$C$7:$C$2046,VLOOKUP(NS!B22,$B$7:$B$62,1,FALSE),'BANK 3'!$F$7:$F$2046)) -> 0 | K22: =G22+I22-H22 -> 0
A23: 3-112 | B23: Prive/Dividen | D23: D | E23: NR | H23: =(SUMIF(KAS!$C$7:$C$1577,VLOOKUP(NS!B23,$B$7:$B$34,1,FALSE),KAS!$G$7:$G$1577))+(SUMIF('BANK 1'!$C$7:$C$1436,VLOOKUP(NS!B23,$B$7:$B$34,1,FALSE),'BANK 1'!$G$7:$G$1436))+(SUMIF('JURNAL PENYESUAIAN'!$C$7:$C$1434,VLOOKUP(NS!B23,$B$7:$B$34,1,FALSE),'JURNAL PENYESUAIAN'!$G$7:$G$1434))+(SUMIF('BANK 4'!$C$7:$C$2046,VLOOKUP(NS!B23,$B$7:$B$34,1,FALSE),'BANK 4'!$G$7:$G$2046))+(SUMIF('BANK 2'!$C$7:$C$2046,VLOOKUP(NS!B23,$B$7:$B$34,1,FALSE),'BANK 2'!$G$7:$G$2046))+(SUMIF('BANK 3'!$C$7:$C$2046,VLOOKUP(NS!B23,$B$7:$B$34,1,FALSE),'BANK 3'!$G$7:$G$2046)) -> 0 | K23: =G23+H23-I23 -> 0
A24: 3-113 | B24: Laba ditahan | D24: K | E24: NR | I24: 0 | K24: =G24+I24-H24 -> 0
A25: 4-114 | B25: Pendapatan | D25: K | E25: LR | I25: ='LABA RUGI'!D7 -> 1.5020892e+08 | K25: =G25+I25-H25 -> 1.5020892e+08
A26: 5-111 | B26: Biaya Sehubungan dengan Jasa | D26: D | E26: LR | H26: ='LABA RUGI'!D11 -> 6000000 | J26: =F26+H26-I26 -> 6000000
A27: 5-112 | B27: Biaya Gaji Karyawan | D27: D | E27: LR | H27: ='LABA RUGI'!D16 -> 0 | J27: =F27+H27-I27 -> 0
A28: 5-113 | B28: Biaya Listrik, Internet, PDAM | D28: D | E28: LR | H28: ='LABA RUGI'!D17 -> 1555000 | J28: =F28+H28-I28 -> 1555000
A29: 5-114 | B29: Biaya BPJS | D29: D | E29: LR | H29: ='LABA RUGI'!D18 -> 5198862 | J29: =F29+H29-I29 -> 5198862
A30: 5-115 | B30: Biaya Operasional | D30: D | E30: LR | H30: ='LABA RUGI'!D19 -> 0 | J30: =F30+H30-I30 -> 0
A31: 5-116 | B31: Biaya Pemasaran | D31: D | E31: LR | H31: ='LABA RUGI'!D20 -> 0 | J31: =F31+H31-I31 -> 0
A32: 5-117 | B32: Biaya Transport | D32: D | E32: LR | H32: ='LABA RUGI'!D21 -> 0 | J32: =F32+H32-I32 -> 0
A33: 5-118 | B33: Biaya Pemeliharaan | D33: D | E33: LR | H33: ='LABA RUGI'!D22 -> 0 | J33: =F33+H33-I33 -> 0
A34: 5-119 | B34: Biaya Sewa | D34: D | E34: LR | H34: ='LABA RUGI'!D23 -> 0 | J34: =F34+H34-I34 -> 0
A35: 5-120 | B35: Biaya Administrasi & Umum | D35: D | E35: LR | H35: ='LABA RUGI'!D24 -> 32500 | J35: =F35+H35-I35 -> 32500
A36: 5-121 | B36: Biaya Depresiasi | D36: D | E36: LR | H36: ='LABA RUGI'!D25 -> 0 | J36: =F36+H36-I36 -> 0
A37: 5-122 | B37: Biaya Pajak | D37: D | E37: LR | H37: ='LABA RUGI'!D26 -> 233463.26 | J37: =F37+H37-I37 -> 233463.26
B38: J U M L A H | F38: =SUM(F7:F37) -> 0 | G38: =SUM(G7:G37) -> 0 | H38: =SUM(H7:H37) -> 1.6322874e+08 | I38: =SUM(I7:I37) -> 2.3946222e+08 | J38: =SUM(J7:J37) -> 73975436 | K38: =SUM(K7:K37) -> 1.5020892e+08

Sheet KAS
B1: LAPORAN TRANSAKSI
B2: PT EDU MEDIA DIGITAL
B3: 2026
F4: =SUBTOTAL(9,F7:F1577) -> 0 | G4: =SUBTOTAL(9,G7:G1577) -> 0
A5: No | B5: TANGGAL | C5: KETERANGAN | D5: URAIAN DETAIL | E5: DARI/KEPADA | F5: PEMASUKAN | G5: PENGELUARAN | H5: SALDO
A6: 1 | C6: SALDO AWAL | H6: =NS!F7 -> 0
A7: 2 | H7: =H6+F7-G7 -> 0
A8: 3 | H8: =H7+F8-G8 -> 0
A9: 4 | H9: =H8+F9-G9 -> 0
A10: 5 | H10: =H9+F10-G10 -> 0
A11: 6 | H11: =H10+F11-G11 -> 0
A12: 7 | H12: =H11+F12-G12 -> 0
A13: 8 | H13: =H12+F13-G13 -> 0
A14: 9 | H14: =H13+F14-G14 -> 0
A15: 10 | H15: =H14+F15-G15 -> 0
A16: 11 | H16: =H15+F16-G16 -> 0
A17: 12 | H17: =H16+F17-G17 -> 0
A18: 13 | H18: =H17+F18-G18 -> 0
... A1575: 1570 | H1575: =H1574+F1575-G1575 -> 0
A1576: 1571 | C1576: Persediaan | D1576: Sisa Persediaan Akhir | F1576: ='PERSEDIAAN STOK'!H2 -> 0 | H1576: =H1575+F1576-G1576 -> 0
A1577: 1572 | C1577: Persediaan | D1577: Sisa Persediaan Akhir | G1577: =F1576 -> 0 | H1577: =H1576+F1577-G1577 -> 0
D1578: TOTAL | F1578: =SUM(F7:F1577) -> 0 | G1578: =SUM(G7:G1577) -> 0
G1580: 4000000
G1581: =G1578/G1580 -> 0

Sheet BANK 1
B1: LAPORAN BANK BRI
B2: =KAS!B2:H2 -> PT EDU MEDIA DIGITAL
B3: =KAS!B3:H3 -> 2026
F4: =SUBTOTAL(9,F7:F1436) -> 1.5020892e+08 | G4: =SUBTOTAL(9,G7:G1436) -> 89253305
A5: No | B5: TANGGAL | C5: KETERANGAN | D5: URAIAN DETAIL | E5: DARI/KEPADA | F5: PEMASUKAN | G5: PENGELUARAN | H5: SALDO
A6: 1 | C6: SALDO AWAL | D6: SISA SALDO DESEMBER 2025 | H6: 1.6852362e+09
A7: 2 | D7: Cloud Nopember 2025 | E7: Jago Febian | F7: 0 | G7: 68233480 | H7: =H6+F7-G7 -> 1.6170028e+09
A8: 3 | C8: Administrasi & Umum | D8: admin bank | F8: 0 | G8: 2500 | H8: =H7+F8-G8 -> 1.6170003e+09
A9: 4 | C9: Pendapatan | F9: 20000000 | G9: 0 | H9: =H8+F9-G9 -> 1.6370003e+09
A10: 5 | C10: Pendapatan | D10: wp perpanjang domain | F10: 590000 | G10: 0 | H10: =H9+F10-G10 -> 1.6375903e+09
A11: 6 | C11: Administrasi & Umum | D11: admin bank | F11: 0 | G11: 2500 | H11: =H10+F11-G11 -> 1.6375878e+09
A12: 7 | C12: Listrik Internet PDAM | D12: internet NEUVIZ | F12: 0 | G12: 555000 | H12: =H11+F12-G12 -> 1.6370328e+09
A13: 8 | C13: BPJS | D13: BPJS kesehatan | F13: 0 | G13: 5198862 | H13: =H12+F13-G13 -> 1.6318339e+09
A14: 9 | C14: Listrik Internet PDAM | D14: internet INDIBIZ | F14: 0 | G14: 1000000 | H14: =H13+F14-G14 -> 1.6308339e+09
A15: 10 | C15: Biaya Jasa | D15: fee client pak Lukman | F15: 0 | G15: 6000000 | H15: =H14+F15-G15 -> 1.6248339e+09
A16: 11 | C16: Administrasi & Umum | D16: admin bank | F16: 0 | G16: 2500 | H16: =H15+F16-G16 -> 1.6248314e+09
A17: 12 | D17: cicilan Grandvilla | F17: 0 | G17: 8000000 | H17: =H16+F17-G17 -> 1.6168314e+09
A18: 13 | C18: Administrasi & Umum | D18: admin bank | F18: 0 | G18: 2500 | H18: =H17+F18-G18 -> 1.6168289e+09
A19: 14 | C19: Pendapatan | D19: Akfis YAB | F19: 1000000 | G19: 0 | H19: =H18+F19-G19 -> 1.6178289e+09
A20: 15 | C20: Pendapatan | D20: STT Migas | F20: 15100000 | G20: 0 | H20: =H19+F20-G20 -> 1.6329289e+09
A21: 16 | C21: Pendapatan | D21: STT Migas | F21: 15100000 | G21: 0 | H21: =H20+F21-G21 -> 1.6480289e+09
A22: 17 | C22: Pendapatan | D22: STT Migas | F22: 15100000 | G22: 0 | H22: =H21+F22-G22 -> 1.6631289e+09
A23: 18 | C23: Pendapatan | D23: Univ. mitra bangsa | F23: 3956000 | G23: 0 | H23: =H22+F23-G23 -> 1.6670849e+09
A24: 19 | C24: Pendapatan | D24: STT Migas | F24: 7550000 | G24: 0 | H24: =H23+F24-G24 -> 1.6746349e+09
A25: 20 | C25: Pendapatan | D25: STIKes sukabumi | F25: 4700000 | G25: 0 | H25: =H24+F25-G25 -> 1.6793349e+09
A26: 21 | C26: Pendapatan | D26: Univ baiturrahim | F26: 3700000 | G26: 0 | H26: =H25+F26-G26 -> 1.6830349e+09
A27: 22 | C27: Pendapatan | D27: STIA lppn padang | F27: 4000000 | G27: 0 | H27: =H26+F27-G27 -> 1.6870349e+09
A28: 23 | C28: Pendapatan | D28: Univ kader bangsa | F28: 3000000 | G28: 0 | H28: =H27+F28-G28 -> 1.6900349e+09
A29: 24 | C29: Pendapatan | D29: ITEKes bali | F29: 6000000 | G29: 0 | H29: =H28+F29-G29 -> 1.6960349e+09
... A45: 40 | C45: Pajak | D45: pajak bank | F45: 0 | G45: 233463.26 | H45: =H44+F45-G45 -> 1.7461918e+09
A46: 41 | H46: =H45+F46-G46 -> 1.7461918e+09
A47: 42 | H47: =H46+F47-G47 -> 1.7461918e+09
A48: 43 | H48: =H47+F48-G48 -> 1.7461918e+09
A49: 44 | H49: =H48+F49-G49 -> 1.7461918e+09
A50: 45 | H50: =H49+F50-G50 -> 1.7461918e+09
H51: =H50+F51-G51 -> 1.7461918e+09
A52: 46 | H52: =H51+F52-G52 -> 1.7461918e+09
A53: 47 | H53: =H52+F53-G53 -> 1.7461918e+09
A54: 48 | H54: =H53+F54-G54 -> 1.7461918e+09
A55: 49 | H55: =H54+F55-G55 -> 1.7461918e+09
...

Sheet BANK 2
B1: LAPORAN TRANSAKSI
B2: PT EDU MEDIA DIGITAL
B3: 2026
F4: =SUBTOTAL(9,F7:F795) -> 0 | G4: =SUBTOTAL(9,G7:G795) -> 0
A5: No | B5: TANGGAL | C5: KETERANGAN | D5: URAIAN DETAIL | E5: DARI/KEPADA | F5: PEMASUKAN | G5: PENGELUARAN | H5: SALDO
A6: 1 | C6: SALDO AWAL | H6: =NS!F9 -> 0
A7: 2 | H7: =H6+F7-G7 -> 0
A8: 3 | H8: =H7+F8-G8 -> 0
A9: 4 | H9: =H8+F9-G9 -> 0
A10: 5 | H10: =H9+F10-G10 -> 0
A11: 6 | H11: =H10+F11-G11 -> 0
A12: 7 | H12: =H11+F12-G12 -> 0
A13: 8 | H13: =H12+F13-G13 -> 0
A14: 9 | H14: =H13+F14-G14 -> 0
A15: 10 | H15: =H14+F15-G15 -> 0
A16: 11 | H16: =H15+F16-G16 -> 0
A17: 12 | H17: =H16+F17-G17 -> 0
A18: 13 | H18: =H17+F18-G18 -> 0
... A129: 124 | H129: =H128+F129-G129 -> 0
H130: =H129+F130-G130 -> 0
H131: =H130+F131-G131 -> 0
H132: =H131+F132-G132 -> 0
H133: =H132+F133-G133 -> 0
H134: =H133+F134-G134 -> 0
H135: =H134+F135-G135 -> 0
H136: =H135+F136-G136 -> 0
H137: =H136+F137-G137 -> 0
H138: =H137+F138-G138 -> 0
H139: =H138+F139-G139 -> 0
H140: =H139+F140-G140 -> 0
H141: =H140+F141-G141 -> 0
... H411: =H410+F411-G411 -> 0
A412: 26 | H412: =H411+F412-G412 -> 0
A413: 27 | H413: =H412+F413-G413 -> 0
A414: 28 | H414: =H413+F414-G414 -> 0
A415: 29 | H415: =H414+F415-G415 -> 0
A416: 30 | H416: =H415+F416-G416 -> 0
A417: 31 | H417: =H416+F417-G417 -> 0
A418: 32 | H418: =H417+F418-G418 -> 0
A419: 33 | H419: =H418+F419-G419 -> 0
...

Sheet BANK 3
B1: LAPORAN TRANSAKSI
B2: =KAS!B2 -> PT EDU MEDIA DIGITAL
B3: 2026
F4: =SUBTOTAL(9,F7:F795) -> 0 | G4: =SUBTOTAL(9,G7:G795) -> 0
A5: No | B5: TANGGAL | C5: KETERANGAN | D5: URAIAN DETAIL | E5: DARI/KEPADA | F5: PEMASUKAN | G5: PENGELUARAN | H5: SALDO
A6: 1 | C6: SALDO AWAL | H6: =NS!F10 -> 0
A7: 2 | H7: =H6+F7-G7 -> 0
A8: 3 | H8: =H7+F8-G8 -> 0
A9: 4 | H9: =H8+F9-G9 -> 0
A10: 5 | H10: =H9+F10-G10 -> 0
A11: 6 | H11: =H10+F11-G11 -> 0
A12: 7 | H12: =H11+F12-G12 -> 0
A13: 8 | H13: =H12+F13-G13 -> 0
A14: 9 | H14: =H13+F14-G14 -> 0
A15: 10 | H15: =H14+F15-G15 -> 0
A16: 11 | H16: =H15+F16-G16 -> 0
A17: 12 | H17: =H16+F17-G17 -> 0
A18: 13 | H18: =H17+F18-G18 -> 0
... A129: 124 | H129: =H128+F129-G129 -> 0
H130: =H129+F130-G130 -> 0
H131: =H130+F131-G131 -> 0
H132: =H131+F132-G132 -> 0
H133: =H132+F133-G133 -> 0
H134: =H133+F134-G134 -> 0
H135: =H134+F135-G135 -> 0
H136: =H135+F136-G136 -> 0
H137: =H136+F137-G137 -> 0
H138: =H137+F138-G138 -> 0
H139: =H138+F139-G139 -> 0
H140: =H139+F140-G140 -> 0
H141: =H140+F141-G141 -> 0
... H411: =H410+F411-G411 -> 0
A412: 26 | H412: =H411+F412-G412 -> 0
A413: 27 | H413: =H412+F413-G413 -> 0
A414: 28 | H414: =H413+F414-G414 -> 0
A415: 29 | H415: =H414+F415-G415 -> 0
A416: 30 | H416: =H415+F416-G416 -> 0
A417: 31 | H417: =H416+F417-G417 -> 0
A418: 32 | H418: =H417+F418-G418 -> 0
A419: 33 | H419: =H418+F419-G419 -> 0
...

Sheet BANK 4
B1: LAPORAN TRANSAKSI
B2: =KAS!B2 -> PT EDU MEDIA DIGITAL
B3: 2026
F4: =SUBTOTAL(9,F7:F2046) -> 0 | G4: =SUBTOTAL(9,G7:G2046) -> 0
A5: No | B5: TANGGAL | C5: KETERANGAN | D5: URAIAN DETAIL | E5: DARI/KEPADA | F5: PEMASUKAN | G5: PENGELUARAN | H5: SALDO
A6: 1 | C6: SALDO AWAL | H6: =NS!F11 -> 0
H7: =H6+F7-G7 -> 0
H8: =H7+F8-G8 -> 0
H9: =H8+F9-G9 -> 0
H10: =H9+F10-G10 -> 0
H11: =H10+F11-G11 -> 0
H12: =H11+F12-G12 -> 0
H13: =H12+F13-G13 -> 0
H14: =H13+F14-G14 -> 0
H15: =H14+F15-G15 -> 0
H16: =H15+F16-G16 -> 0
H17: =H16+F17-G17 -> 0
H18: =H17+F18-G18 -> 0
... H36: =H35+F36-G36 -> 0
H37: =H36+F37-G37 -> 0 | J37: =F36-G37 -> 0
H38: =H37+F38-G38 -> 0
H39: =H38+F39-G39 -> 0
H40: =H39+F40-G40 -> 0
H41: =H40+F41-G41 -> 0
H42: =H41+F42-G42 -> 0
H43: =H42+F43-G43 -> 0
H44: =H43+F44-G44 -> 0
H45: =H44+F45-G45 -> 0 | J45: =F44-G45-G46 -> 0
H46: =H45+F46-G46 -> 0
H47: =H46+F47-G47 -> 0
H48: =H47+F48-G48 -> 0
H49: =H48+F49-G49 -> 0
H50: =H49+F50-G50 -> 0
H51: =H50+F51-G51 -> 0
H52: =H51+F52-G52 -> 0
H53: =H52+F53-G53 -> 0
H54: =H53+F54-G54 -> 0
H55: =H54+F55-G55 -> 0
H56: =H55+F56-G56 -> 0
H57: =H56+F57-G57 -> 0
...

Sheet JURNAL PENYESUAIAN
B1: LAPORAN JURNAL
B2: =KAS!B2:H2 -> PT EDU MEDIA DIGITAL
B3: =KAS!B3:H3 -> 2026
F4: =SUBTOTAL(9,F7:F1434) -> 0 | G4: =SUBTOTAL(9,G7:G1434) -> 0
A5: No | B5: TANGGAL | C5: KETERANGAN | D5: URAIAN DETAIL | E5: DARI/KEPADA | F5: PEMASUKAN | G5: PENGELUARAN | H5: SALDO
H7: =H6+F7-G7 -> 0
H8: =H7+F8-G8 -> 0
H9: =H8+F9-G9 -> 0
H10: =H9+F10-G10 -> 0
H11: =H10+F11-G11 -> 0
H12: =H11+F12-G12 -> 0
H13: =H12+F13-G13 -> 0
H14: =H13+F14-G14 -> 0
H15: =H14+F15-G15 -> 0
H16: =H15+F16-G16 -> 0
H17: =H16+F17-G17 -> 0
H18: =H17+F18-G18 -> 0
... H1434: =H1433+F1434-G1434 -> 0
C1435: 1 | D1435: TOTAL | F1435: =SUM(F7:F1434) -> 0 | G1435: =SUM(G7:G1434) -> 0
G1437: 4

Sheet PERSEDIAAN STOK
A1: LAPORAN STOCK OPNAME PERSEDIAAN AKHIR | H1: TOTAL NILAI PERSEDIAAN AKHIR YANG MASUK DI LAPORAN KEUANGAN
A2: =[60]KAS!B3 -> 2025 | H2: =F1007 -> 0
A4: No | B4: Nama Barang | C4: Satuan | D4: Qty | E4: Harga Satuan | F4: Total
A5: 1 | F5: =D5*E5 -> 0
A6: 2 | F6: =D6*E6 -> 0
A7: 3 | F7: =D7*E7 -> 0
A8: 4 | F8: =D8*E8 -> 0
A9: 5 | F9: =D9*E9 -> 0
A10: 6 | F10: =D10*E10 -> 0
A11: 7 | F11: =D11*E11 -> 0
A12: 8 | F12: =D12*E12 -> 0
A13: 9 | F13: =D13*E13 -> 0
A14: 10 | F14: =D14*E14 -> 0
A15: 11 | F15: =D15*E15 -> 0
A16: 12 | F16: =D16*E16 -> 0
... A1006: 1002 | F1006: =D1006*E1006 -> 0
B1007: Total | F1007: =SUM(F5:F1006) -> 0

Sheet ASET
A1: DAFTAR ASET DAN PENYUSUTAN
A3: NO | B3: JENIS ASET | C3: TANGGAL PEROLEHAN | D3: UMUR EKONOMIS | E3: HARGA PEROLEHAN | F3: BEBAN DEPRESIASI | S3: TOTAL BEBAN DEPRESIASI | T3: AKUM. DEPRESIASI TAHUN INI | U3: NILAI BUKU | V3: KETERANGAN
F4: TAHUN 2024 | G4: JAN 2025 | H4: FEB 2025 | I4: MAR 2025 | J4: APR 2025 | K4: MEI 2025 | L4: JUN 2025 | M4: JUL 2025 | N4: AGU 2025 | O4: SEP 2025 | P4: OKT 2025 | Q4: NOV 2025 | R4: DES 2025
B5: TANAH DAN BANGUNAN
A6: 1 | D6: =20*12 -> 240 | S6: =SUM(G6:R6) -> 0 | T6: =S6+F6 -> 0 | U6: =E6-T6 -> 0
A7: 2 | D7: =20*12 -> 240 | S7: =SUM(G7:R7) -> 0 | T7: =S7+F7 -> 0 | U7: =E7-T7 -> 0
A8: 3 | D8: =20*12 -> 240 | S8: =SUM(G8:R8) -> 0 | T8: =S8+F8 -> 0 | U8: =E8-T8 -> 0
A9: 4 | D9: =20*12 -> 240 | S9: =SUM(G9:R9) -> 0 | T9: =S9+F9 -> 0 | U9: =E9-T9 -> 0
A10: 5 | D10: =20*12 -> 240 | S10: =SUM(G10:R10) -> 0 | T10: =S10+F10 -> 0 | U10: =E10-T10 -> 0
A11: 6 | D11: =20*12 -> 240 | S11: =SUM(G11:R11) -> 0 | T11: =S11+F11 -> 0 | U11: =E11-T11 -> 0
A12: 7 | S12: =SUM(G12:R12) -> 0 | T12: =S12+F12 -> 0 | U12: =E12-T12 -> 0
A13: 8 | S13: =SUM(G13:R13) -> 0 | T13: =S13+F13 -> 0 | U13: =E13-T13 -> 0
B14: TOTAL TANAH DAN BANGUNAN | E14: =SUM(E6:E13) -> 0 | F14: =SUM(F6:F13) -> 0 | G14: =SUM(G6:G13) -> 0 | H14: =SUM(H6:H13) -> 0 | I14: =SUM(I6:I13) -> 0 | J14: =SUM(J6:J13) -> 0 | K14: =SUM(K6:K13) -> 0 | L14: =SUM(L6:L13) -> 0 | ... U14: =SUM(U6:U13) -> 0
B16: KENDARAAN
A17: 1 | D17: =8*12 -> 96 | S17: =SUM(G17:R17) -> 0 | T17: =S17+F17 -> 0 | U17: =E17-T17 -> 0
A18: 2 | D18: =8*12 -> 96 | S18: =SUM(G18:R18) -> 0 | T18: =S18+F18 -> 0 | U18: =E18-T18 -> 0
A19: 3 | D19: =8*12 -> 96 | S19: =SUM(G19:R19) -> 0 | T19: =S19+F19 -> 0 | U19: =E19-T19 -> 0
A20: 4 | D20: =8*12 -> 96 | S20: =SUM(G20:R20) -> 0 | T20: =S20+F20 -> 0 | U20: =E20-T20 -> 0
A21: 5 | D21: =8*12 -> 96 | S21: =SUM(G21:R21) -> 0 | T21: =S21+F21 -> 0 | U21: =E21-T21 -> 0
A22: 6 | D22: =8*12 -> 96 | S22: =SUM(G22:R22) -> 0 | T22: =S22+F22 -> 0 | U22: =E22-T22 -> 0
A23: 7 | D23: =8*12 -> 96 | S23: =SUM(G23:R23) -> 0 | T23: =S23+F23 -> 0 | U23: =E23-T23 -> 0
A24: 8 | D24: =8*12 -> 96 | S24: =SUM(G24:R24) -> 0 | T24: =S24+F24 -> 0 | U24: =E24-T24 -> 0
A25: 9 | D25: =8*12 -> 96 | S25: =SUM(G25:R25) -> 0 | T25: =S25+F25 -> 0 | U25: =E25-T25 -> 0
A26: 10 | D26: =8*12 -> 96 | S26: =SUM(G26:R26) -> 0 | T26: =S26+F26 -> 0 | U26: =E26-T26 -> 0
A27: 11 | D27: =8*12 -> 96 | S27: =SUM(G27:R27) -> 0 | T27: =S27+F27 -> 0 | U27: =E27-T27 -> 0
A28: 12 | D28: =8*12 -> 96 | S28: =SUM(G28:R28) -> 0 | T28: =S28+F28 -> 0 | U28: =E28-T28 -> 0
... A30: 14 | D30: =8*12 -> 96 | S30: =SUM(G30:R30) -> 0 | T30: =S30+F30 -> 0 | U30: =E30-T30 -> 0
B31: TOTAL KENDARAAN | E31: =SUM(E17:E30) -> 0 | F31: =SUM(F17:F30) -> 0 | G31: =SUM(G17:G30) -> 0 | H31: =SUM(H17:H30) -> 0 | I31: =SUM(I17:I30) -> 0 | J31: =SUM(J17:J30) -> 0 | K31: =SUM(K17:K30) -> 0 | L31: =SUM(L17:L30) -> 0 | ... U31: =SUM(U17:U30) -> 0
B33: FURNITURE
A34: 1 | D34: =8*12 -> 96 | S34: =SUM(G34:R34) -> 0 | T34: =S34+F34 -> 0 | U34: =E34-T34 -> 0
A35: 2 | D35: =8*12 -> 96 | S35: =SUM(G35:R35) -> 0 | T35: =S35+F35 -> 0 | U35: =E35-T35 -> 0
A36: 3 | D36: =8*12 -> 96 | S36: =SUM(G36:R36) -> 0 | T36: =S36+F36 -> 0 | U36: =E36-T36 -> 0
A37: 4 | D37: =8*12 -> 96 | S37: =SUM(G37:R37) -> 0 | T37: =S37+F37 -> 0 | U37: =E37-T37 -> 0
A38: 5 | D38: =8*12 -> 96 | S38: =SUM(G38:R38) -> 0 | T38: =S38+F38 -> 0 | U38: =E38-T38 -> 0
A39: 6 | D39: =8*12 -> 96 | S39: =SUM(G39:R39) -> 0 | T39: =S39+F39 -> 0 | U39: =E39-T39 -> 0
A40: 7 | D40: =8*12 -> 96 | S40: =SUM(G40:R40) -> 0 | T40: =S40+F40 -> 0 | U40: =E40-T40 -> 0
A41: 8 | D41: =8*12 -> 96 | S41: =SUM(G41:R41) -> 0 | T41: =S41+F41 -> 0 | U41: =E41-T41 -> 0
B42: TOTAL FURNITURE | E42: =SUM(E34:E41) -> 0 | F42: =SUM(F34:F41) -> 0 | G42: =SUM(G34:G41) -> 0 | H42: =SUM(H34:H41) -> 0 | I42: =SUM(I34:I41) -> 0 | J42: =SUM(J34:J41) -> 0 | K42: =SUM(K34:K41) -> 0 | L42: =SUM(L34:L41) -> 0 | ... U42: =SUM(U34:U41) -> 0
B44: PERALATAN
A45: 1 | D45: =4*12 -> 48 | S45: =SUM(G45:R45) -> 0 | T45: =S45+F45 -> 0 | U45: =E45-T45 -> 0
...

Sheet LABA RUGI
B2: LAPORAN LABA RUGI
B3: =KAS!B2:H2 -> PT EDU MEDIA DIGITAL
B4: ='BANK 4'!B3 -> 2026
B6: Pendapatan
B7: Pendapatan | C7: Pendapatan | D7: =(SUMIF(KAS!$C$7:$C$1577,VLOOKUP('LABA RUGI'!C7,$C$7:$C$60,1,FALSE),KAS!$F$7:$F$1577))+(SUMIF('BANK 1'!$C$7:$C$1436,VLOOKUP('LABA RUGI'!C7,$C$7:$C$60,1,FALSE),'BANK 1'!$F$7:$F$1436))+(SUMIF('JURNAL PENYESUAIAN'!$C$7:$C$1434,VLOOKUP('LABA RUGI'!C7,$C$7:$C$60,1,FALSE),'JURNAL PENYESUAIAN'!$F$7:$F$1434))+(SUMIF('BANK 4'!$C$7:$C$2046,VLOOKUP('LABA RUGI'!C7,$C$7:$C$60,1,FALSE),'BANK 4'!$F$7:$F$2046))+(SUMIF('BANK 2'!$C$7:$C$2046,VLOOKUP('LABA RUGI'!C7,$C$7:$C$60,1,FALSE),'BANK 2'!$F$7:$F$2046))+(SUMIF('BANK 3'!$C$7:$C$2046,VLOOKUP('LABA RUGI'!C7,$C$7:$C$60,1,FALSE),'BANK 3'!$F$7:$F$2046)) -> 1.5020892e+08
B8: Jumlah Pendapatan | E8: =SUM(D7:D7) -> 1.5020892e+08
B10: Biaya Jasa
B11: Biaya Sehubungan dengan Jasa | C11: Biaya Jasa | D11: =(SUMIF(KAS!$C$7:$C$1577,VLOOKUP('LABA RUGI'!C11,$C$10:$C$32,1,FALSE),KAS!$G$7:$G$1577))+(SUMIF('BANK 1'!$C$7:$C$1436,VLOOKUP('LABA RUGI'!C11,$C$10:$C$32,1,FALSE),'BANK 1'!$G$7:$G$1436))+(SUMIF('JURNAL PENYESUAIAN'!$C$7:$C$1434,VLOOKUP('LABA RUGI'!C11,$C$10:$C$32,1,FALSE),'JURNAL PENYESUAIAN'!$G$7:$G$1434))+(SUMIF('BANK 4'!$C$7:$C$2046,VLOOKUP('LABA RUGI'!C11,$C$10:$C$32,1,FALSE),'BANK 4'!$G$7:$G$2046))+(SUMIF('BANK 2'!$C$7:$C$2046,VLOOKUP('LABA RUGI'!C11,$C$10:$C$32,1,FALSE),'BANK 2'!$G$7:$G$2046))+(SUMIF('BANK 3'!$C$7:$C$2046,VLOOKUP('LABA RUGI'!C11,$C$10:$C$32,1,FALSE),'BANK 3'!$G$7:$G$2046)) -> 6000000 | I11: PERHITUNGAN PPH TAHUNAN BADAN
B12: Jumlah Biaya Jasa | E12: =D11 -> 6000000 | J12: Jumlah Pendapatan Satu Tahun | K12: =D7 -> 1.5020892e+08
B13: LABA KOTOR | E13: =E8-E12 -> 1.4420892e+08
J14: Hitungan Pajak:
B15: Biaya Operasional | J15: 0,5% x Omset | K15: =K12*0.5% -> 751044.58
B16: Biaya Gaji Karyawan | C16: Gaji | D16: =(SUMIF(KAS!$C$7:$C$1577,VLOOKUP('LABA RUGI'!C16,$C$10:$C$32,1,FALSE),KAS!$G$7:$G$1577))+(SUMIF('BANK 1'!$C$7:$C$1436,VLOOKUP('LABA RUGI'!C16,$C$10:$C$32,1,FALSE),'BANK 1'!$G$7:$G$1436))+(SUMIF('JURNAL PENYESUAIAN'!$C$7:$C$1434,VLOOKUP('LABA RUGI'!C16,$C$10:$C$32,1,FALSE),'JURNAL PENYESUAIAN'!$G$7:$G$1434))+(SUMIF('BANK 4'!$C$7:$C$2046,VLOOKUP('LABA RUGI'!C16,$C$10:$C$32,1,FALSE),'BANK 4'!$G$7:$G$2046))+(SUMIF('BANK 2'!$C$7:$C$2046,VLOOKUP('LABA RUGI'!C16,$C$10:$C$32,1,FALSE),'BANK 2'!$G$7:$G$2046))+(SUMIF('BANK 3'!$C$7:$C$2046,VLOOKUP('LABA RUGI'!C16,$C$10:$C$32,1,FALSE),'BANK 3'!$G$7:$G$2046)) -> 0
B17: Biaya Listrik, Internet, PDAM | C17: Listrik Internet PDAM | D17: =(SUMIF(KAS!$C$7:$C$1577,VLOOKUP('LABA RUGI'!C17,$C$10:$C$32,1,FALSE),KAS!$G$7:$G$1577))+(SUMIF('BANK 1'!$C$7:$C$1436,VLOOKUP('LABA RUGI'!C17,$C$10:$C$32,1,FALSE),'BANK 1'!$G$7:$G$1436))+(SUMIF('JURNAL PENYESUAIAN'!$C$7:$C$1434,VLOOKUP('LABA RUGI'!C17,$C$10:$C$32,1,FALSE),'JURNAL PENYESUAIAN'!$G$7:$G$1434))+(SUMIF('BANK 4'!$C$7:$C$2046,VLOOKUP('LABA RUGI'!C17,$C$10:$C$32,1,FALSE),'BANK 4'!$G$7:$G$2046))+(SUMIF('BANK 2'!$C$7:$C$2046,VLOOKUP('LABA RUGI'!C17,$C$10:$C$32,1,FALSE),'BANK 2'!$G$7:$G$2046))+(SUMIF('BANK 3'!$C$7:$C$2046,VLOOKUP('LABA RUGI'!C17,$C$10:$C$32,1,FALSE),'BANK 3'!$G$7:$G$2046)) -> 1555000
B18: Biaya BPJS | C18: BPJS | D18: =(SUMIF(KAS!$C$7:$C$1577,VLOOKUP('LABA RUGI'!C18,$C$10:$C$32,1,FALSE),KAS!$G$7:$G$1577))+(SUMIF('BANK 1'!$C$7:$C$1436,VLOOKUP('LABA RUGI'!C18,$C$10:$C$32,1,FALSE),'BANK 1'!$G$7:$G$1436))+(SUMIF('JURNAL PENYESUAIAN'!$C$7:$C$1434,VLOOKUP('LABA RUGI'!C18,$C$10:$C$32,1,FALSE),'JURNAL PENYESUAIAN'!$G$7:$G$1434))+(SUMIF('BANK 4'!$C$7:$C$2046,VLOOKUP('LABA RUGI'!C18,$C$10:$C$32,1,FALSE),'BANK 4'!$G$7:$G$2046))+(SUMIF('BANK 2'!$C$7:$C$2046,VLOOKUP('LABA RUGI'!C18,$C$10:$C$32,1,FALSE),'BANK 2'!$G$7:$G$2046))+(SUMIF('BANK 3'!$C$7:$C$2046,VLOOKUP('LABA RUGI'!C18,$C$10:$C$32,1,FALSE),'BANK 3'!$G$7:$G$2046)) -> 5198862
B19: Biaya Operasional | C19: Operasional | D19: =(SUMIF(KAS!$C$7:$C$1577,VLOOKUP('LABA RUGI'!C19,$C$10:$C$32,1,FALSE),KAS!$G$7:$G$1577))+(SUMIF('BANK 1'!$C$7:$C$1436,VLOOKUP('LABA RUGI'!C19,$C$10:$C$32,1,FALSE),'BANK 1'!$G$7:$G$1436))+(SUMIF('JURNAL PENYESUAIAN'!$C$7:$C$1434,VLOOKUP('LABA RUGI'!C19,$C$10:$C$32,1,FALSE),'JURNAL PENYESUAIAN'!$G$7:$G$1434))+(SUMIF('BANK 4'!$C$7:$C$2046,VLOOKUP('LABA RUGI'!C19,$C$10:$C$32,1,FALSE),'BANK 4'!$G$7:$G$2046))+(SUMIF('BANK 2'!$C$7:$C$2046,VLOOKUP('LABA RUGI'!C19,$C$10:$C$32,1,FALSE),'BANK 2'!$G$7:$G$2046))+(SUMIF('BANK 3'!$C$7:$C$2046,VLOOKUP('LABA RUGI'!C19,$C$10:$C$32,1,FALSE),'BANK 3'!$G$7:$G$2046)) -> 0 | I19: PPH 25
B20: Biaya Pemasaran | C20: Pemasaran | D20: =(SUMIF(KAS!$C$7:$C$1577,VLOOKUP('LABA RUGI'!C20,$C$10:$C$32,1,FALSE),KAS!$G$7:$G$1577))+(SUMIF('BANK 1'!$C$7:$C$1436,VLOOKUP('LABA RUGI'!C20,$C$10:$C$32,1,FALSE),'BANK 1'!$G$7:$G$1436))+(SUMIF('JURNAL PENYESUAIAN'!$C$7:$C$1434,VLOOKUP('LABA RUGI'!C20,$C$10:$C$32,1,FALSE),'JURNAL PENYESUAIAN'!$G$7:$G$1434))+(SUMIF('BANK 4'!$C$7:$C$2046,VLOOKUP('LABA RUGI'!C20,$C$10:$C$32,1,FALSE),'BANK 4'!$G$7:$G$2046))+(SUMIF('BANK 2'!$C$7:$C$2046,VLOOKUP('LABA RUGI'!C20,$C$10:$C$32,1,FALSE),'BANK 2'!$G$7:$G$2046))+(SUMIF('BANK 3'!$C$7:$C$2046,VLOOKUP('LABA RUGI'!C20,$C$10:$C$32,1,FALSE),'BANK 3'!$G$7:$G$2046)) -> 0 | J20: Pajak PPh Final UMKM PP 55 2022 | K20: =K15 -> 751044.58
B21: Biaya Transport | C21: Transport | D21: =(SUMIF(KAS!$C$7:$C$1577,VLOOKUP('LABA RUGI'!C21,$C$10:$C$32,1,FALSE),KAS!$G$7:$G$1577))+(SUMIF('BANK 1'!$C$7:$C$1436,VLOOKUP('LABA RUGI'!C21,$C$10:$C$32,1,FALSE),'BANK 1'!$G$7:$G$1436))+(SUMIF('JURNAL PENYESUAIAN'!$C$7:$C$1434,VLOOKUP('LABA RUGI'!C21,$C$10:$C$32,1,FALSE),'JURNAL PENYESUAIAN'!$G$7:$G$1434))+(SUMIF('BANK 4'!$C$7:$C$2046,VLOOKUP('LABA RUGI'!C21,$C$10:$C$32,1,FALSE),'BANK 4'!$G$7:$G$2046))+(SUMIF('BANK 2'!$C$7:$C$2046,VLOOKUP('LABA RUGI'!C21,$C$10:$C$32,1,FALSE),'BANK 2'!$G$7:$G$2046))+(SUMIF('BANK 3'!$C$7:$C$2046,VLOOKUP('LABA RUGI'!C21,$C$10:$C$32,1,FALSE),'BANK 3'!$G$7:$G$2046)) -> 0
B22: Biaya Pemeliharaan | C22: Pemeliharaan | D22: =(SUMIF(KAS!$C$7:$C$1577,VLOOKUP('LABA RUGI'!C22,$C$10:$C$32,1,FALSE),KAS!$G$7:$G$1577))+(SUMIF('BANK 1'!$C$7:$C$1436,VLOOKUP('LABA RUGI'!C22,$C$10:$C$32,1,FALSE),'BANK 1'!$G$7:$G$1436))+(SUMIF('JURNAL PENYESUAIAN'!$C$7:$C$1434,VLOOKUP('LABA RUGI'!C22,$C$10:$C$32,1,FALSE),'JURNAL PENYESUAIAN'!$G$7:$G$1434))+(SUMIF('BANK 4'!$C$7:$C$2046,VLOOKUP('LABA RUGI'!C22,$C$10:$C$32,1,FALSE),'BANK 4'!$G$7:$G$2046))+(SUMIF('BANK 2'!$C$7:$C$2046,VLOOKUP('LABA RUGI'!C22,$C$10:$C$32,1,FALSE),'BANK 2'!$G$7:$G$2046))+(SUMIF('BANK 3'!$C$7:$C$2046,VLOOKUP('LABA RUGI'!C22,$C$10:$C$32,1,FALSE),'BANK 3'!$G$7:$G$2046)) -> 0
B23: Biaya Sewa | C23: Sewa | D23: =(SUMIF(KAS!$C$7:$C$1577,VLOOKUP('LABA RUGI'!C23,$C$10:$C$32,1,FALSE),KAS!$G$7:$G$1577))+(SUMIF('BANK 1'!$C$7:$C$1436,VLOOKUP('LABA RUGI'!C23,$C$10:$C$32,1,FALSE),'BANK 1'!$G$7:$G$1436))+(SUMIF('JURNAL PENYESUAIAN'!$C$7:$C$1434,VLOOKUP('LABA RUGI'!C23,$C$10:$C$32,1,FALSE),'JURNAL PENYESUAIAN'!$G$7:$G$1434))+(SUMIF('BANK 4'!$C$7:$C$2046,VLOOKUP('LABA RUGI'!C23,$C$10:$C$32,1,FALSE),'BANK 4'!$G$7:$G$2046))+(SUMIF('BANK 2'!$C$7:$C$2046,VLOOKUP('LABA RUGI'!C23,$C$10:$C$32,1,FALSE),'BANK 2'!$G$7:$G$2046))+(SUMIF('BANK 3'!$C$7:$C$2046,VLOOKUP('LABA RUGI'!C23,$C$10:$C$32,1,FALSE),'BANK 3'!$G$7:$G$2046)) -> 0
B24: Biaya Administrasi & Umum | C24: Administrasi & Umum | D24: =(SUMIF(KAS!$C$7:$C$1577,VLOOKUP('LABA RUGI'!C24,$C$10:$C$32,1,FALSE),KAS!$G$7:$G$1577))+(SUMIF('BANK 1'!$C$7:$C$1436,VLOOKUP('LABA RUGI'!C24,$C$10:$C$32,1,FALSE),'BANK 1'!$G$7:$G$1436))+(SUMIF('JURNAL PENYESUAIAN'!$C$7:$C$1434,VLOOKUP('LABA RUGI'!C24,$C$10:$C$32,1,FALSE),'JURNAL PENYESUAIAN'!$G$7:$G$1434))+(SUMIF('BANK 4'!$C$7:$C$2046,VLOOKUP('LABA RUGI'!C24,$C$10:$C$32,1,FALSE),'BANK 4'!$G$7:$G$2046))+(SUMIF('BANK 2'!$C$7:$C$2046,VLOOKUP('LABA RUGI'!C24,$C$10:$C$32,1,FALSE),'BANK 2'!$G$7:$G$2046))+(SUMIF('BANK 3'!$C$7:$C$2046,VLOOKUP('LABA RUGI'!C24,$C$10:$C$32,1,FALSE),'BANK 3'!$G$7:$G$2046)) -> 32500
B25: Biaya Depresiasi/Penyusutan | D25: =ASET!S86 -> 0
B26: Biaya Pajak | C26: Pajak | D26: =(SUMIF(KAS!$C$7:$C$1577,VLOOKUP('LABA RUGI'!C26,$C$10:$C$32,1,FALSE),KAS!$G$7:$G$1577))+(SUMIF('BANK 1'!$C$7:$C$1436,VLOOKUP('LABA RUGI'!C26,$C$10:$C$32,1,FALSE),'BANK 1'!$G$7:$G$1436))+(SUMIF('JURNAL PENYESUAIAN'!$C$7:$C$1434,VLOOKUP('LABA RUGI'!C26,$C$10:$C$32,1,FALSE),'JURNAL PENYESUAIAN'!$G$7:$G$1434))+(SUMIF('BANK 4'!$C$7:$C$2046,VLOOKUP('LABA RUGI'!C26,$C$10:$C$32,1,FALSE),'BANK 4'!$G$7:$G$2046))+(SUMIF('BANK 2'!$C$7:$C$2046,VLOOKUP('LABA RUGI'!C26,$C$10:$C$32,1,FALSE),'BANK 2'!$G$7:$G$2046))+(SUMIF('BANK 3'!$C$7:$C$2046,VLOOKUP('LABA RUGI'!C26,$C$10:$C$32,1,FALSE),'BANK 3'!$G$7:$G$2046)) -> 233463.26
B27: Jumlah Biaya Operasional | E27: =SUM(D16:D26) -> 7019825.3
B28: LABA (RUGI) OPERASIONAL | E28: =E13-E27 -> 1.3718909e+08
B30: Pendapatan & Biaya Luar Usaha
B31: Pendapatan Luar Usaha | C31: PLU | D31: =(SUMIF(KAS!$C$7:$C$1577,VLOOKUP('LABA RUGI'!C31,$C$7:$C$60,1,FALSE),KAS!$F$7:$F$1577))+(SUMIF('BANK 1'!$C$7:$C$1436,VLOOKUP('LABA RUGI'!C31,$C$7:$C$60,1,FALSE),'BANK 1'!$F$7:$F$1436))+(SUMIF('JURNAL PENYESUAIAN'!$C$7:$C$1434,VLOOKUP('LABA RUGI'!C31,$C$7:$C$60,1,FALSE),'JURNAL PENYESUAIAN'!$F$7:$F$1434))+(SUMIF('BANK 4'!$C$7:$C$2046,VLOOKUP('LABA RUGI'!C31,$C$7:$C$60,1,FALSE),'BANK 4'!$F$7:$F$2046))+(SUMIF('BANK 2'!$C$7:$C$2046,VLOOKUP('LABA RUGI'!C31,$C$7:$C$60,1,FALSE),'BANK 2'!$F$7:$F$2046))+(SUMIF('BANK 3'!$C$7:$C$2046,VLOOKUP('LABA RUGI'!C31,$C$7:$C$60,1,FALSE),'BANK 3'!$F$7:$F$2046)) -> 0
B32: Biaya Luar Usaha | C32: BLU | D32: =(SUMIF(KAS!$C$7:$C$1577,VLOOKUP('LABA RUGI'!C32,$C$10:$C$32,1,FALSE),KAS!$G$7:$G$1577))+(SUMIF('BANK 1'!$C$7:$C$1436,VLOOKUP('LABA RUGI'!C32,$C$10:$C$32,1,FALSE),'BANK 1'!$G$7:$G$1436))+(SUMIF('JURNAL PENYESUAIAN'!$C$7:$C$1434,VLOOKUP('LABA RUGI'!C32,$C$10:$C$32,1,FALSE),'JURNAL PENYESUAIAN'!$G$7:$G$1434))+(SUMIF('BANK 4'!$C$7:$C$2046,VLOOKUP('LABA RUGI'!C32,$C$10:$C$32,1,FALSE),'BANK 4'!$G$7:$G$2046))+(SUMIF('BANK 2'!$C$7:$C$2046,VLOOKUP('LABA RUGI'!C32,$C$10:$C$32,1,FALSE),'BANK 2'!$G$7:$G$2046))+(SUMIF('BANK 3'!$C$7:$C$2046,VLOOKUP('LABA RUGI'!C32,$C$10:$C$32,1,FALSE),'BANK 3'!$G$7:$G$2046)) -> 0
B33: Total | E33: =D31-D32 -> 0
B34: LABA (RUGI) BERSIH | E34: =E28+E33 -> 1.3718909e+08
D41: …...................., 31 Desember 2026
D46: …..............................
D47: Direktur Utama

Sheet NERACA
A1: LAPORAN NERACA
A2: ='LABA RUGI'!B3 -> PT EDU MEDIA DIGITAL
A3: ='LABA RUGI'!B4 -> 2026
A5: ASET | F5: LIABILITAS & EKUITAS
A6: Aset Lancar | F6: Liabilitas
A7: Kas dan Bank | B7: =NS!J7+NS!J8+NS!J9+NS!J10+NS!J11 -> 60955611 | F7: Hutang Usaha | G7: =NS!K21 -> 0
A8: Piutang Usaha | B8: =NS!J12 -> 0 | F8: PPN Keluaran | G8: =NS!K18 -> 0
A9: PPh 23 Dibayar Dimuka | B9: =NS!J13 -> 0
A10: PPh 22 Dibayar Dimuka | B10: =NS!J14 -> 0 | F10: Jumlah Hutang Lancar | H10: =SUM(G7:G9) -> 0
A11: PPh 25 Dibayar Dimuka | B11: =NS!J15 -> 0
A12: PPN Masukan | B12: =NS!J16 -> 0
A13: PPN Dibayar Dimuka (Instansi) | B13: =NS!J17 -> 0 | F13: Ekuitas
A14: Jumlah Aset Lancar | C14: =SUM(B7:B13) -> 60955611 | F14: Modal Disetor | G14: =LPM!C5 -> 0
F15: Prive/Dividen | G15: =LPM!B9 -> 0
A16: Aset Tetap | F16: Laba (Rugi) ditahan sebelumnya | G16: =LPM!B7 -> 0
A17: Aset | B17: =ASET!E86 -> 0 | F17: Laba (Rugi) ditahan berjalan | G17: =LPM!B8 -> 1.3718909e+08
A18: Akumulasi Penyusutan | B18: =-ASET!T86 -> 0 | F18: Jumlah Ekuitas | H18: =SUM(G14:G17) -> 1.3718909e+08
A19: Jumlah Aset Tetap | C19: =SUM(B17:B18) -> 0
A21: Total Aset | C21: =C14+C19 -> 60955611 | F21: TOTAL LIABILITAS & EKUITAS | H21: =H10+H18 -> 1.3718909e+08
H22: =H21-C21 -> 76233480
F24: …...................., 31 Desember 2026
F29: …..............................
F30: Direktur Utama

Sheet LPM
A1: ='LABA RUGI'!B3 -> PT EDU MEDIA DIGITAL
A2: LAPORAN PERUBAHAN MODAL
A3: ='LABA RUGI'!B4 -> 2026
A5: Modal awal Pemilik | C5: =NS!K22 -> 0
A7: Laba ditahan | B7: =NS!K24 -> 0
A8: Laba Berjalan | B8: ='LABA RUGI'!E34 -> 1.3718909e+08
A9: Prive/Dividen | B9: =-NS!K23 -> 0
C10: =SUM(B7:B9) -> 1.3718909e+08
A11: Modal akhir Pemilik | C11: =C5+C10 -> 1.3718909e+08

Sheet PEREDARAN BRUTO
A1: Daftar Jumlah Penghasilan Bruto dan Pembayaran PPh Final berdasarkan PP 55 Tahun 2022
A2: Per Masa Pajak Serta Dari Masing-Masing Tempat Usaha
B4: Nama | C4: =KAS!B2 -> PT EDU MEDIA DIGITAL
B5: NPWP | C5: 0
B6: Alamat | C6: -
A8: No. | B8: NPWP Tempat Usaha | C8: Alamat | D8: Peredaran Bruto | E8: PPh Final
B10: KPP Lokasi
A11: 1. | B11: =C5 -> 0
B12: Januari | C12: =$C$6 -> - | E12: =D12*0.5% -> 0
B13: Februari | C13: =$C$6 -> - | E13: =D13*0.5% -> 0
B14: Maret | C14: =$C$6 -> - | E14: =D14*0.5% -> 0
B15: April | C15: =$C$6 -> - | E15: =D15*0.5% -> 0
B16: Mei | C16: =$C$6 -> - | E16: =D16*0.5% -> 0
B17: Juni | C17: =$C$6 -> - | E17: =D17*0.5% -> 0
B18: Juli | C18: =$C$6 -> - | E18: =D18*0.5% -> 0
B19: Agustus | C19: =$C$6 -> - | E19: =D19*0.5% -> 0
B20: September | C20: =$C$6 -> - | E20: =D20*0.5% -> 0
B21: Oktober | C21: =$C$6 -> - | E21: =D21*0.5% -> 0
B22: November | C22: =$C$6 -> - | E22: =D22*0.5% -> 0
B23: Desember | C23: =$C$6 -> - | E23: =D23*0.5% -> 0
A25: Jumlah | D25: =SUM(D11:D24) -> 0 | E25: =SUM(E11:E24) -> 0
D29: ='LABA RUGI'!D41 -> …...................., 31 Desember 2026
D34: ='[61]LABA RUGI'!D45 -> …..............................
D35: =[62]IDENTITAS!B20 -> DIREKTUR UTAMA

Sheet LABA RUGI PAJAK
A1: LAPORAN LABA RUGI SESUAI CORETAX
A2: =[63]LPM!A1 -> (NAMA PERUSAHAAN)
A3: =[63]LPM!A3 -> 2025
A5: KODE AKUN | B5: NAMA AKUN | C5: NILAI KOMERSIAL | D5: TIDAK TERMASUK OBJEK PAJAK | E5: DIKENAKAN PPH BERSIFAT FINAL | F5: OBJEK PAJAK TIDAK FINAL | G5: PENYESUAIAN FISKAL POSITIF | H5: PENYESUAIAN FISKAL NEGATIF | I5: NILAI FISKAL
B6: Pendapatan:
A7: 4021 | B7: Pendapatan Jasa | C7: ='LABA RUGI'!D7 -> 1.5020892e+08 | F7: =C7-D7-E7 -> 1.5020892e+08 | H7: =C7 -> 1.5020892e+08 | I7: =C7-D7-E7+G7-H7 -> 0
A8: 4013 | B8: Penyesuaian Penjualan | C8: 0 | F8: =C8-D8-E8 -> 0 | G8: =C8 -> 0 | I8: =C8+H8-G8 -> 0
A9: 5020 | B9: Biaya Pokok Jasa | C9: ='LABA RUGI'!D11 -> 6000000 | G9: =C9 -> 6000000 | I9: =C9+H9-G9 -> 0
A10: 4300 | B10: Laba Kotor | C10: =C7-C8-C9 -> 1.4420892e+08 | D10: =D7-D8-D9 -> 0 | E10: =E7-E8-E9 -> 0 | F10: =F7-F8-F9 -> 1.5020892e+08 | G10: =G7-G8-G9 -> -6000000 | H10: =H7-H8-H9 -> 1.5020892e+08 | I10: =I7-I8-I9 -> 0
A11: 4199 | B11: Pendapatan Lainnya | C11: 0 | F11: =C11-D11-E11 -> 0 | H11: =C11 -> 0 | I11: =C11-D11-E11+G11-H11 -> 0
B12: Beban Usaha:
A13: 5311 | B13: Gaji, Tunjangan, Bonus, Honorarium, THR, dsb | C13: ='LABA RUGI'!D16 -> 0 | G13: =C13 -> 0 | I13: =C13+H13-G13 -> 0
A14: 5312 | B14: Beban Imbalan Kerja Lainnya | C14: ='LABA RUGI'!D18 -> 5198862 | G14: =C14 -> 5198862 | I14: =C14+H14-G14 -> 0
A15: 5313 | B15: Beban Transportasi | C15: ='LABA RUGI'!D21 -> 0 | G15: =C15 -> 0 | I15: =C15+H15-G15 -> 0
A16: 5314 | B16: Beban Penyusutan dan Amortisasi | C16: ='LABA RUGI'!D25 -> 0 | G16: =C16 -> 0 | I16: =C16+H16-G16 -> 0
A17: 5315 | B17: Beban Sewa | C17: ='LABA RUGI'!D23 -> 0 | G17: =C17 -> 0 | I17: =C17+H17-G17 -> 0
A18: 5316 | B18: Beban Bunga | G18: =C18 -> 0 | I18: =C18+H18-G18 -> 0
A19: 5317 | B19: Beban Sehubungan dengan Jasa | C19: 0 | G19: =C19 -> 0 | I19: =C19+H19-G19 -> 0
A20: 5318 | B20: Beban Penurunan Nilai | G20: =C20 -> 0 | I20: =C20+H20-G20 -> 0
A21: 5319 | B21: Beban Royalti | G21: =C21 -> 0 | I21: =C21+H21-G21 -> 0
A22: 5320 | B22: Beban Pemasaran atau Promosi | C22: ='LABA RUGI'!D20 -> 0 | G22: =C22 -> 0 | I22: =C22+H22-G22 -> 0
A23: 5321 | B23: Beban Entertainment | G23: =C23 -> 0 | I23: =C23+H23-G23 -> 0
A24: 5399 | B24: Beban usaha lainnya | G24: =C24 -> 0 | I24: =C24+H24-G24 -> 0
A25: 5400 | B25: Jumlah Beban Usaha | C25: =SUM(C13:C24) -> 5198862 | G25: =SUM(G13:G24) -> 5198862 | H25: =SUM(H13:H24) -> 0 | I25: =SUM(I13:I24) -> 0
A26: 4500 | B26: Laba (Rugi) Usaha | C26: =C10+C11-C25 -> 1.3901005e+08 | G26: =G10+G11-G25 -> -11198862 | H26: =H10+H11-H25 -> 1.5020892e+08 | I26: =I10+I11-I25 -> 0
B27: Pendapatan Non Usaha:
A28: 4501 | B28: Keuntungan Selisih Kurs | F28: =C28-D28-E28 -> 0 | H28: =C28 -> 0 | I28: =C28-D28-E28+G28-H28 -> 0
A29: 4503 | B29: Keuntungan Penjualan Aset selain Persediaan | F29: =C29-D29-E29 -> 0 | H29: =C29 -> 0 | I29: =C29-D29-E29+G29-H29 -> 0
A30: 4511 | B30: Pendapatan Bunga (Komponen Pembiayaan pada Kontrak Pelanggan) | F30: =C30-D30-E30 -> 0 | H30: =C30 -> 0 | I30: =C30-D30-E30+G30-H30 -> 0
A31: 4599 | B31: Pendapatan Non Usaha Lainnya | C31: ='LABA RUGI'!D31 -> 0 | F31: =C31-D31-E31 -> 0 | H31: =C31 -> 0 | I31: =C31-D31-E31+G31-H31 -> 0
A32: 4600 | B32: Jumlah Pendapatan Non Usaha | C32: =SUM(C28:C31) -> 0 | G32: =SUM(G28:G31) -> 0 | H32: =SUM(H28:H31) -> 0 | I32: =SUM(I28:I31) -> 0
B33: Beban Non Usaha:
A34: 5405 | B34: Kerugian Penjualan Aset selain Persediaan | G34: =C34 -> 0 | I34: =C34+H34-G34 -> 0
A35: 5409 | B35: Sumbangan | G35: =C35 -> 0 | I35: =C35+H35-G35 -> 0
A36: 5421 | B36: Kerugian Selisih Kurs | G36: =C36 -> 0 | I36: =C36+H36-G36 -> 0
A37: 5499 | B37: Beban Non Usaha Lainnya | C37: ='LABA RUGI'!D32 -> 0 | G37: =C37 -> 0 | I37: =C37+H37-G37 -> 0
A38: 5500 | B38: Jumlah Beban Non Usaha | C38: =SUM(C34:C37) -> 0 | G38: =SUM(G34:G37) -> 0 | H38: =SUM(H34:H37) -> 0 | I38: =SUM(I34:I37) -> 0
A39: 4700 | B39: Laba (Rugi) Non Usaha | C39: =C32-C38 -> 0 | G39: =G32-G38 -> 0 | H39: =H32-H38 -> 0 | I39: =I32-I38 -> 0
A40: 4800 | B40: Laba (Rugi) Sebelum Pajak | C40: =C26+C39 -> 1.3901005e+08 | G40: =G26+G39 -> -11198862 | H40: =H26+H39 -> 1.5020892e+08 | I40: =I26+I39 -> 0
H42: …...................., 31 Desember 2026
...

Sheet NERACA PAJAK
A1: LAPORAN POSISI KEUANGAN SESUAI CORETAX
A2: ='[63]LABA RUGI PAJAK'!A2 -> (NAMA PERUSAHAAN)
A3: ='[63]LABA RUGI PAJAK'!A3 -> 2025
A5: Kode Akun | B5: Nama Akun | C5: Nominal | E5: Kode Akun | F5: Nama Akun | G5: Nominal
B6: Aset Lancar | F6: Liabilitas Jangka Pendek
A7: 1101 | B7: Kas dan Setara Kas | C7: =NERACA!B7 -> 60955611 | E7: 2102 | F7: Utang Usaha - Pihak Ketiga | G7: =NERACA!G7 -> 0
A8: 1122 | B8: Piutang Usaha - Pihak Ketiga | C8: =NERACA!B8 -> 0 | E8: 2103 | F8: Utang Usaha - Pihak yang Mempunyai Hubungan Istimewa
A9: 1123 | B9: Piutang Usaha - Pihak yang Mempunyai Hubungan Istimewa | E9: 2111 | F9: Utang Bunga
A10: 1124 | B10: Piutang Lainnya - Pihak Ketiga | E10: 2191 | F10: Utang Pajak | G10: =NERACA!G8 -> 0
A11: 1125 | B11: Piutang Lainnya - Pihak yang Mempunyai Hubungan Istimewa | E11: 2186 | F11: Liabilitas Kontrak
A12: 1131 | B12: Cadangan Kerugian Penurunan Nilai - Aset Tidak Lancar | E12: 2187 | F12: Liabilitas Sewa Jangka Pendek
A13: 1181 | B13: Aset Kontrak | E13: 2192 | F13: Utang Dividen
A14: 1200 | B14: Investasi | E14: 2195 | F14: Beban yang Masih Harus Dibayar
A15: 1401 | B15: Persediaan | E15: 2201 | F15: Utang Bank Jangka Pendek
A16: 1421 | B16: Beban Dibayar di Muka | E16: 2202 | F16: Utang Jangka Panjang yang Jatuh Tempo dalam Satu Tahun
A17: 1422 | B17: Uang Muka | E17: 2203 | F17: Pendapatan Diterima di Muka
A18: 1423 | B18: Pajak Dibayar di Muka | C18: =NERACA!B9+NERACA!B10+NERACA!B11+NERACA!B12+NERACA!B13 -> 0 | E18: 2228 | F18: Liabilitas Jangka Pendek Lainnya
A19: 1499 | B19: Aset lancar lainnya | E19: 2229 | F19: Jumlah Liabilitas Jangka Pendek | G19: =SUM(G7:G18) -> 0
A20: 1500 | B20: Jumlah Aset Lancar | C20: =SUM(C7:C19) -> 60955611
B21: Aset Tidak Lancar | F21: Liabilitas Jangka Panjang
A22: 1501 | B22: Piutang Jangka Panjang | E22: 2301 | F22: Utang Bank Jangka Panjang
A23: 1521 | B23: Aset Tetap dan Inventaris | C23: =ASET!E86 -> 0 | E23: 2303 | F23: Utang Jangka Panjang-Pihak Ketiga
A24: 1522 | B24: Dikurangi: Akumulasi Penyusutan Aset Tetap dan Inventaris | C24: =ASET!T86 -> 0 | E24: 2304 | F24: Utang Jangka Panjang - Pihak yang Mempunyai Hubungan Istimewa
A25: 1551 | B25: Investasi pada Perusahaan Asosiasi, Ventura Bersama dan Anak Perusahaan | E25: 2312 | F25: Liabilitas Sewa Jangka Panjang
A26: 1599 | B26: Investasi Jangka Panjang Lainnya | E26: 2322 | F26: Liabilitas Imbalan Kerja
A27: 1600 | B27: Aset Tak Berwujud | E27: 2321 | F27: Liabilitas Pajak Tangguhan
A28: 1601 | B28: Dikurangi : Akumulasi Amortisasi-Aset Tak Berwujud | E28: 2998 | F28: Liabilitas Jangka Panjang Lainnya
A29: 1611 | B29: Aktiva Pajak Tangguhan | E29: 2999 | F29: Jumlah Liabilitas | G29: =SUM(G19:G28) -> 0
A30: 1651 | B30: Klaim atas pengembalian pajak
A31: 1658 | B31: Cadangan Kerugian Penurunan Nilai - Aset Tidak Lancar | F31: Equity
A32: 1698 | B32: Aset Tidak Lancar Lainnya | E32: 3102 | F32: Modal Saham | G32: =NERACA!G14 -> 0
A33: 1699 | B33: Jumlah Aset Tidak Lancar | C33: =C22+C23-C24+C25+C26+C27-C28+C29+C30+C31+C32 -> 0 | E33: 3120 | F33: Tambahan Modal Disetor
E34: 3200 | F34: Laba Ditahan | G34: =NERACA!G16+NERACA!G17 -> 1.3718909e+08
A35: 1700 | B35: Jumlah Aset | C35: =C20+C33 -> 60955611 | E35: 3297 | F35: Pendapatan Komprehensif Lainnya
E36: 3298 | F36: Ekuitas Lainnya | G36: =NERACA!G15 -> 0
E37: 3299 | F37: Jumlah Ekuitas | G37: =SUM(G32:G36) -> 1.3718909e+08
E39: 3300 | F39: Jumlah Liabilitas dan Ekuitas | G39: =G29+G37 -> 1.3718909e+08
F42: …...................., 31 Desember 2026
F47: …..............................
F48: Direktur Utama

Sheet RASIO KEUANGAN
A1: RASIO PROFITABILITAS
B3: RETURN ON EQUITY | C3: = | D3: LABA OPERASIONAL | E3: X 100% | G3: ='LABA RUGI'!E28 -> 1.3718909e+08 | H3: X 100% | I3: = | J3: =IFERROR(G3/G4,0) -> 1
B4: (ROE) | D4: JUMLAH EKUITAS | G4: =NERACA!H18 -> 1.3718909e+08
B7: RETURN ON ASSET | C7: = | D7: LABA OPERASIONAL | E7: X 100% | G7: =G3 -> 1.3718909e+08 | H7: X 100% | I7: = | J7: =IFERROR(G7/G8,0) -> 2.2506393
B8: (ROA) | D8: JUMLAH ASET | G8: =NERACA!C21 -> 60955611
B11: GROSS PROFIT RATIO | C11: = | D11: LABA KOTOR | E11: X 100% | G11: ='LABA RUGI'!E13 -> 1.4420892e+08 | H11: X 100% | I11: = | J11: =IFERROR(G11/G12,0) -> 0.96005563
D12: PENJUALAN | G12: ='LABA RUGI'!E8 -> 1.5020892e+08
B15: OPERATING PROFIT RATIO | C15: = | D15: LABA OPERASIONAL | E15: X 100% | G15: =G7 -> 1.3718909e+08 | H15: X 100% | I15: = | J15: =IFERROR(G15/G16,0) -> 0.91332189
D16: PENJUALAN | G16: ='LABA RUGI'!E8 -> 1.5020892e+08
B19: NET PROFIT RATIO | C19: = | D19: LABA BERSIH | E19: X 100% | G19: ='LABA RUGI'!E34 -> 1.3718909e+08 | H19: X 100% | I19: = | J19: =IFERROR(G19/G20,0) -> 0.91332189
D20: PENJUALAN | G20: ='LABA RUGI'!E8 -> 1.5020892e+08
A24: RASIO LIKUIDITAS
B26: CURRENT RATIO | C26: = | D26: ASET LANCAR | G26: =NERACA!C14 -> 60955611 | I26: = | J26: =IFERROR(G26/G27,0) -> 0
B27: RASIO LANCAR | D27: UTANG JANGKA PENDEK | G27: =NERACA!H10 -> 0
B31: CASH RATIO | C31: = | D31: KAS DAN SETARA KAS | G31: =NERACA!B7 -> 60955611 | I31: = | J31: =IFERROR(G31/G32,0) -> 0
B32: RASIO KAS | D32: UTANG JANGKA PENDEK | G32: =NERACA!H10 -> 0
A35: RASIO SOLVABILITAS
B37: DEBT TO EQUITY RATIO | C37: = | D37: JUMLAH HUTANG | G37: =NERACA!H10 -> 0 | I37: = | J37: =IFERROR(G37/G38,0) -> 0
B38: (DER) | D38: JUMLAH EKUITAS | G38: =NERACA!H18 -> 1.3718909e+08
B41: DEBT TO ASSET RATIO | C41: = | D41: JUMLAH HUTANG | E41: X 100% | G41: =NERACA!H10 -> 0 | H41: X 100% | I41: = | J41: =IFERROR(G41/G42,0) -> 0
B42: (DAR) | D42: JUMLAH ASET | G42: =NERACA!C21 -> 60955611
